<?xml version="1.0"?>
<robot  xmlns:xacro="http://www.ros.org/wiki/xacro" name="firefighter" >
	
<xacro:property name="width" value=".2" />


  <link name="base">
    <visual>
      <geometry>
       <mesh filename="package://mycobot_description/urdf/mycobot_pro_450/PRO450_J1.dae"/>
      </geometry>
      <origin xyz = "-0.108 -0.003 0 " rpy = " 0 0 -1.5708"/>
    </visual>
    <collision>
      <geometry>
       <mesh filename="package://mycobot_description/urdf/mycobot_pro_450/PRO450_J1.dae"/>
        </geometry>
        <origin xyz = "-0.108 -0.003 0 " rpy = " 0 0 -1.5708"/>
    </collision>
  </link>

  <link name="link1">
    <visual>
      <geometry>
       <mesh filename="package://mycobot_description/urdf/mycobot_pro_450/PRO450_J2.dae"/>
      </geometry>
      <origin xyz = "0.0015 -0.0392 0.0 " rpy = " -1.5708 0 -3.14159 "/>
    </visual>
    <collision>
     <geometry>
       <mesh filename="package://mycobot_description/urdf/mycobot_pro_450/PRO450_J2.dae"/>
      </geometry>
      <origin xyz = "0.0015 -0.0392 0.0 " rpy = " -1.5708 0 -3.14159 "/>
    </collision>
  </link>

  <link name="link2">
    <visual>
      <geometry>
       <mesh filename="package://mycobot_description/urdf/mycobot_pro_450/PRO450_J3.dae"/>
      </geometry>
    <origin xyz = "0.0598 0.005 -0.203 " rpy = " 0 0 1.5708 "/>
    </visual>
    <collision>
      <geometry>
       <mesh filename="package://mycobot_description/urdf/mycobot_pro_450/PRO450_J3.dae"/>
      </geometry>
      <origin xyz = "0.0598  0.005 -0.203 " rpy = " 0 0 1.5708"/>
    </collision>
  </link>

  <link name="link3">
    <visual>
      <geometry>
       
       <mesh filename="package://mycobot_description/urdf/mycobot_pro_450/PRO450_J4.dae"/>
      </geometry>
      <origin xyz = "0.07 0.005 -0.383 " rpy = " 0 0 1.5708"/>
    </visual>
    <collision>
      <geometry>
       <mesh filename="package://mycobot_description/urdf/mycobot_pro_450/PRO450_J4.dae"/>
      </geometry>
      <origin xyz = "0.07 0.005 -0.383" rpy = " 0 0 1.5708"/>
    </collision>
  </link>


  <link name="link4">
    <visual>
      <geometry>
       <mesh filename="package://mycobot_description/urdf/mycobot_pro_450/PRO450_J5.dae"/>
      </geometry>
    <origin xyz = "-0.014 0 0.0 " rpy = " 0 -1.5708 0"/>
    </visual>
    <collision>
       <geometry>
       <mesh filename="package://mycobot_description/urdf/mycobot_pro_450/PRO450_J5.dae"/>
      </geometry>
      <origin xyz = "-0.014 0 0.0 " rpy = " 0 -1.5708 0"/>
    </collision>
  </link>


  <link name="link5">
    <visual>
      <geometry>
       
       <mesh filename="package://mycobot_description/urdf/mycobot_pro_450/PRO450_J6.dae"/>
      </geometry>
    <origin xyz = "0.004 -0.024 -0.655 " rpy = " 0 0 0"/>
    </visual>
    <collision>
      <geometry>
       
       <mesh filename="package://mycobot_description/urdf/mycobot_pro_450/PRO450_J6.dae"/>
      </geometry>
    <origin xyz = "0.004 -0.024 -0.655 " rpy = " 0 0 0"/>
    </collision>
  </link>


  <link name="link6">
    <visual>
      <geometry>
       
       <mesh filename="package://mycobot_description/urdf/mycobot_pro_450/PRO450_J6_end.dae"/>
      </geometry>
    <origin xyz = "0 0 0 " rpy = " 3.14159 0 0"/>
    </visual>
    <collision>
      <geometry>
       
       <mesh filename="package://mycobot_description/urdf/mycobot_pro_450/PRO450_J6_end.dae"/>
      </geometry>
    <origin xyz = "0 0 0 " rpy = " 3.14159 0 0"/>
    </collision>
  </link>


  <link name="gripper_connection">
    <visual>
      <geometry>
       <mesh filename="package://mycobot_description/urdf/force_control_gripper/mygripper_f100_connection.dae"/>
      </geometry>
    <origin xyz = "-0.03 0.014 0 " rpy = " 0  0 -1.5708"/>
    </visual>
    <collision>
      <geometry>
       <mesh filename="package://mycobot_description/urdf/force_control_gripper/mygripper_f100_connection.dae"/>
      </geometry>
    <origin xyz = "-0.03 0.014 0 " rpy = " 0  0 -1.5708"/>
    </collision>
  </link>


  <link name="gripper_base">
    <visual>
      <geometry>
       <mesh filename="package://mycobot_description/urdf/force_control_gripper/pro_gripper_base.dae"/>
      </geometry>
    <origin xyz = "-0.107 0.012 0.0 " rpy = " 1.5708  0 1.5708"/>
    </visual>
    <collision>
      <geometry>
       <mesh filename="package://mycobot_description/urdf/force_control_gripper/pro_gripper_base.dae"/>
      </geometry>
    <origin xyz = "-0.107 0.012 0.0 " rpy = " 1.5708  0 1.5708"/>
    </collision>
  </link>

  <link name="gripper_left1">
    <visual>
      <geometry>
       <!--- 0.0 0 -0.04 -->
       <mesh filename="package://mycobot_description/urdf/force_control_gripper/pro_gripper_left1.dae"/>
      </geometry>
    <origin xyz = "-0.047 -0.013 0.044 " rpy = " 1.5708 0 1.5708"/>
    </visual>
    <collision>
      <geometry>
       <mesh filename="package://mycobot_description/urdf/force_control_gripper/pro_gripper_left1.dae"/>
      </geometry>
        <origin xyz = "-0.047 -0.013 0.044 " rpy = " 1.5708 0 1.5708"/>
    </collision>
  </link>

  <link name="gripper_left2">
    <visual>
      <geometry>
       <mesh filename="package://mycobot_description/urdf/force_control_gripper/pro_gripper_left2.dae"/>
      </geometry>
    <origin xyz = "-0.0 0.03 0.004 " rpy = " 3.14159 0 1.5708"/>
    </visual>
    <collision>
      <geometry>
       <mesh filename="package://mycobot_description/urdf/force_control_gripper/pro_gripper_left2.dae"/>
      </geometry>
        <origin xyz = "-0.0 0.03 0.004 " rpy = " 3.14159 0 1.5708"/>
    </collision>
  </link>

  <link name="gripper_left3">
    <visual>
      <geometry>
       <mesh filename="package://mycobot_description/urdf/force_control_gripper/pro_gripper_left3.dae"/>
      </geometry>
    <origin xyz = "0 -0.03 0.012 " rpy = " 1.5708 3.14159 1.5708"/>

    </visual>
    <collision>
      <geometry>
       <mesh filename="package://mycobot_description/urdf/force_control_gripper/pro_gripper_left3.dae"/>
      </geometry>
    <origin xyz = "0 -0.03 0.012 " rpy = " 1.5708 3.14159 1.5708"/>
    </collision>
  </link>

  <link name="gripper_right1">
    <visual>
      <geometry>
       <mesh filename="package://mycobot_description/urdf/force_control_gripper/pro_gripper_right1.dae"/>
      </geometry>
    <origin xyz = "0.047 -0.013 -0.046 " rpy = " 1.5708 3.14 -1.5708"/>
    </visual>
    <collision>
      <geometry>
       <mesh filename="package://mycobot_description/urdf/force_control_gripper/pro_gripper_right1.dae"/>
      </geometry>
        <origin xyz = "0.047 -0.013 -0.046 " rpy = " 1.5708 3.14 -1.5708"/>
    </collision>
  </link>

  <link name="gripper_right2">
    <visual>
      <geometry>
       <mesh filename="package://mycobot_description/urdf/force_control_gripper/pro_gripper_right2.dae"/>
      </geometry>
    <origin xyz = "0 0.03 -0.005 " rpy = " 0 0 1.5708"/>
    </visual>
    <collision>
      <geometry>
       <mesh filename="package://mycobot_description/urdf/force_control_gripper/pro_gripper_right2.dae"/>
      </geometry>
        <origin xyz = "0 0.03 -0.005 " rpy = " 0 0 1.5708"/>
    </collision>
  </link>

  <link name="gripper_right3">
    <visual>
      <geometry>
       <mesh filename="package://mycobot_description/urdf/force_control_gripper/pro_gripper_right3.dae"/>
      </geometry>
    <origin xyz = "-0.014 -0.029 0.004 " rpy = " 3.14 0 -1.5708"/>

    </visual>
    <collision>
      <geometry>
       <mesh filename="package://mycobot_description/urdf/force_control_gripper/pro_gripper_right3.dae"/>
      </geometry>
    <origin xyz = "-0.014 -0.029 0.004 " rpy = " 3.14 0 -1.5708"/>
    </collision>
  </link>


  <joint name="joint1" type="revolute">
    <axis xyz="0 0 1"/>
    <limit effort = "1000.0" lower = "-2.8274" upper = "2.8274" velocity = "0"/>
    <parent link="base"/>
    <child link="link1"/>
    <origin xyz= "0 0 0.210" rpy = "0 0 0"/>  
  </joint>


  <joint name="joint2" type="revolute">
    <axis xyz="1 0 0"/>
    <limit effort = "1000.0" lower = "-1.9896" upper = "1.9896" velocity = "0"/>
    <parent link="link1"/>
    <child link="link2"/>
    <origin xyz= "0.0 -0.048 0" rpy = "0 0 -1.5708"/>  
  </joint>


  <joint name="joint3" type="revolute">
    <axis xyz=" 1 0 0"/>
    <limit effort = "1000.0" lower = "-2.6878" upper = "2.6878" velocity = "0"/>
    <parent link="link2"/>
    <child link="link3"/>
    <origin xyz= "-0.01 0 0.18  " rpy = "0 0 0"/>  
  </joint>


  <joint name="joint4" type="revolute">
    <axis xyz=" 1 0 0"/>
    <limit effort = "1000.0" lower = "-2.8274" upper = "2.8274" velocity = "0"/>
    <parent link="link3"/>
    <child link="link4"/>
    <origin xyz= "0 0 0.173" rpy = "0 0 0"/>  
  </joint>


  <joint name="joint5" type="revolute">
    <axis xyz="0 0 1"/>
    <limit effort = "1000.0" lower = "-2.8274" upper = "2.8274" velocity = "0"/>
    <parent link="link4"/>
    <child link="link5"/>
    <origin xyz= "0.0455 0 0.097" rpy = "0 0 0"/>  
  </joint>

 
  <joint name="joint6" type="revolute">
    <axis xyz="1 0 0"/>
    <limit effort = "1000.0" lower = "-2.8797" upper = "2.8797" velocity = "0"/>
    <parent link="link5"/>
    <child link="link6"/>
    <origin xyz= "0 0.04 0" rpy = "0 0 1.5708"/>  
  </joint>


  <joint name="joint6_to_gripper_connect" type="fixed">
    <parent link="link6"/>
    <child link="gripper_connection"/>
     <origin xyz= "0.03 0.0 -0.01" rpy = "-1.5708 0 -1.5708"/>
  </joint> 

  <joint name="joint6_to_gripper_base" type="fixed">
    <parent link="gripper_connection"/>
    <child link="gripper_base"/>
     <origin xyz= "0 -0.02 0.0364" rpy = "1.5708 0 0"/>
  </joint>

  <joint name="gripper_controller" type="revolute">
    <axis xyz="0 0 1"/>
    <limit effort = "1000.0" lower = "0" upper = "1" velocity = "0"/>
    <parent link="gripper_base"/>
    <child link="gripper_left3"/>
    <origin xyz= "-0.018 0.016 -0.02" rpy = "0 0 0"/> 
  </joint>

  <joint name="gripper_base_to_gripper_left2" type="revolute">
    <axis xyz="0 0 1"/>
    <limit effort = "1000.0" lower = "-0.8" upper = "0.5" velocity = "0"/>
    <parent link="gripper_base"/>
    <child link="gripper_left2"/>
    <origin xyz= "-0.0445 -0.004 -0.02" rpy = "0 0 0"/> 
    <mimic joint="gripper_controller" multiplier="1.0" offset="0" />
  </joint>

  <joint name="gripper_left3_to_gripper_left1" type="revolute">
    <axis xyz="0 0 1"/>
    <limit effort = "1000.0" lower = "-0.5" upper = "0.5" velocity = "0"/>
    <parent link="gripper_left3"/>
    <child link="gripper_left1"/>
    <origin xyz= "0.01 0.06 0.0" rpy = "0 0 0"/> 
    <mimic joint="gripper_controller" multiplier="-1.0" offset="0" />
  </joint>

  <joint name="gripper_base_to_gripper_right3" type="revolute">
    <axis xyz="0 0 1"/>
    <limit effort = "1000.0" lower = "1" upper = "0" velocity = "0"/>
    <parent link="gripper_base"/>
    <child link="gripper_right3"/>
    <origin xyz= "0.018 0.015 -0.0212" rpy = "0 0 0"/> 
    <mimic joint="gripper_controller" multiplier="-1.0" offset="0" />
  </joint>

  <joint name="gripper_base_to_gripper_right2" type="revolute">
    <axis xyz="0 0 1"/>
    <limit effort = "1000.0" lower = "-0.5" upper = "0.8" velocity = "0"/>
    <parent link="gripper_base"/>
    <child link="gripper_right2"/>
    <origin xyz= "0.0442 -0.004 -0.02" rpy = "0 0 0"/> 
    <mimic joint="gripper_controller" multiplier="-1.0" offset="0" />
  </joint>

  <joint name="gripper_right3_to_gripper_right1" type="revolute">
    <axis xyz="0 0 1"/>
    <limit effort = "1000.0" lower = "-0.5" upper = "0.5" velocity = "0"/>
    <parent link="gripper_right3"/>
    <child link="gripper_right1"/>
    <origin xyz= "-0.01 0.061 0.001" rpy = "0 0 0"/> 
    <mimic joint="gripper_controller" multiplier="1.0" offset="0" />
  </joint>

</robot>

