<?xml version="1.0" ?>
<!-- =================================================================================== -->
<!-- |    This document was autogenerated by xacro from /home/lijie/桌面/demo_test2/src/mycobot_320_description/urdf/robot_robotiq85_gripper.xacro | -->
<!-- |    EDITING THIS FILE BY HAND IS NOT RECOMMENDED                                 | -->
<!-- =================================================================================== -->
<robot name="ur5">
    <!-- World Link -->
    <link name="world" />
    <!-- Base Joint -->
    <joint name="base_joint" type="fixed">
        <parent link="world" />
        <child link="base" />
         <origin xyz="0 0.05 0.215" rpy="0 0 0" />
    </joint>
    <!-- Base Link -->
    <link name="base">
        <visual>
            <geometry>
                <mesh filename="package://mycobot_320_description/urdf/mycobot_320_m5_2022/base.dae" />
            </geometry>
            <origin rpy="0 0 1.5708" xyz="0.0 0 0" />
        </visual>
        <collision>
            <origin rpy="0 0 1.5708" xyz="0.0 0.0 0.05" />
            <geometry>
                <cylinder length="0.05" radius="0.053" />
            </geometry>
        </collision>
        <selfCollide>true</selfCollide>
        <inertial>
            <mass value="1000.0" />
            <inertia ixx="100" ixy="0.0" ixz="0.0" iyy="100" iyz="0.0" izz="100" />
            <origin xyz="0 0 0" rpy="0 0 0" />
        </inertial>
    </link>
    <!-- Link 1 -->
    <link name="link1">
        <visual>
            <geometry>
                <mesh filename="package://mycobot_320_description/urdf/mycobot_320_m5_2022/link1.dae" />
            </geometry>
            <origin rpy="0 0 1.5708" xyz="0.0 0.0 -0.078" />
        </visual>
        <collision>
            <origin rpy="0 0 1.5708" xyz="0.0 0 -0.05" />
            <geometry>
                <cylinder length="0.1" radius="0.033" />
            </geometry>
        </collision>
        <selfCollide>true</selfCollide>
        <inertial>
            <mass value="10.0" />
            <inertia ixx="1" ixy="0.0" ixz="0.0" iyy="1" iyz="0.0" izz="1" />
            <origin xyz="0 0 0" rpy="0 0 0" />
        </inertial>
    </link>
    <!-- Link 2 -->
    <link name="link2">
        <visual>
            <geometry>
                <mesh filename="package://mycobot_320_description/urdf/mycobot_320_m5_2022/link2.dae" />
            </geometry>
            <origin rpy="0 1.5708 0" xyz="0.0 0.0 -0.04" />
        </visual>
        <collision>
            <origin rpy="0 1.5708 0" xyz="0.065 0 0" />
            <geometry>
                <cylinder length="0.15" radius="0.024" />
            </geometry>
        </collision>
        <selfCollide>true</selfCollide>
        <inertial>
            <mass value="5.0" />
            <inertia ixx="0.5" ixy="0.0" ixz="0.0" iyy="0.5" iyz="0.0" izz="0.5" />
            <origin xyz="0 0 0" rpy="0 0 0" />
        </inertial>
    </link>
    <!-- Link 3 -->
    <link name="link3">
        <visual>
            <geometry>
                <mesh filename="package://mycobot_320_description/urdf/mycobot_320_m5_2022/link3.dae" />
            </geometry>
            <origin rpy="1.5708 1.5708 1.5708" xyz="0.0 0.0 0.039" />
        </visual>
        <collision>
            <origin rpy="1.5708 1.5708 1.5708" xyz="0.062 0.0 -0.01" />
            <geometry>
                <cylinder length="0.14" radius="0.0205" />
            </geometry>
        </collision>
        <selfCollide>true</selfCollide>
        <inertial>
            <mass value="5.0" />
            <inertia ixx="0.5" ixy="0.0" ixz="0.0" iyy="0.5" iyz="0.0" izz="0.5" />
            <origin xyz="0 0 0" rpy="0 0 0" />
        </inertial>
    </link>
    <!-- Link 4 -->
    <link name="link4">
        <visual>
            <geometry>
                <mesh filename="package://mycobot_320_description/urdf/mycobot_320_m5_2022/link4.dae" />
            </geometry>
            <origin rpy="1.5708 1.5708 0" xyz="0.0 -0.0024 -0.05" />
        </visual>
        <collision>
            <origin rpy="0 0 1.5708" xyz="0.0 -0.0024 -0.05" />
            <geometry>
                <cylinder length="0.09" radius="0.024" />
            </geometry>
        </collision>
        <selfCollide>true</selfCollide>
        <inertial>
            <mass value="2.0" />
            <inertia ixx="0.2" ixy="0.0" ixz="0.0" iyy="0.2" iyz="0.0" izz="0.2" />
            <origin xyz="0 0 0" rpy="0 0 0" />
        </inertial>
    </link>
    <!-- Link 5 -->
    <link name="link5">
        <visual>
            <geometry>
                <mesh filename="package://mycobot_320_description/urdf/mycobot_320_m5_2022/link5.dae" />
            </geometry>
            <origin rpy="0 0 -1.5708" xyz="0.0 0.0 -0.05" />
        </visual>
        <collision>
            <origin rpy="0 0 -1.5708" xyz="0.0 0.0 -0.05" />
            <geometry>
                <cylinder length="0.1" radius="0.019" />
            </geometry>
        </collision>
        <selfCollide>true</selfCollide>
        <inertial>
            <mass value="2.0" />
            <inertia ixx="0.2" ixy="0.0" ixz="0.0" iyy="0.2" iyz="0.0" izz="0.2" />
            <origin xyz="0 0 0" rpy="0 0 0" />
        </inertial>
    </link>
    <!-- Link 6 -->
    <link name="link6">
        <visual>
            <geometry>
                <mesh filename="package://mycobot_320_description/urdf/mycobot_320_m5_2022/link6.dae" />
            </geometry>
            <origin rpy="1.5708 1.5708 0" xyz="0.0 0.0 -0.0115" />
        </visual>
        <collision>
            <origin rpy="0 0 1.5708" xyz="0.0 0.0 0" />
            <geometry>
                <cylinder length="0.015" radius="0.026" />
            </geometry>
        </collision>
        <selfCollide>true</selfCollide>
        <inertial>
            <mass value="2.0" />
            <inertia ixx="0.2" ixy="0.0" ixz="0.0" iyy="0.2" iyz="0.0" izz="0.2" />
            <origin xyz="0 0 0" rpy="0 0 0" />
        </inertial>
    </link>
    <!-- Gripper Connection -->
    <link name="gripper_connection">
        <visual>
            <geometry>
                <mesh filename="package://mycobot_320_description/urdf/mycobot_320_m5_2022/force_control_gripper/mygripper_f100_connection.dae" />
            </geometry>
            <origin rpy="0 0 -1.5708" xyz="-0.03 0.014 0" />
        </visual>
        <collision>
            <geometry>
                <mesh filename="package://mycobot_320_description/urdf/mycobot_320_m5_2022/force_control_gripper/mygripper_f100_connection.dae" />
            </geometry>
            <origin rpy="0 0 -1.5708" xyz="-0.03 0.014 0" />
        </collision>
        <selfCollide>true</selfCollide>
        <inertial>
            <mass value="1.0" />
            <inertia ixx="0.1" ixy="0.0" ixz="0.0" iyy="0.1" iyz="0.0" izz="0.1" />
            <origin xyz="0 0 0" rpy="0 0 0" />
        </inertial>
    </link>
    <!-- Gripper Base -->
    <link name="gripper_base">
        <visual>
            <geometry>
                <mesh filename="package://mycobot_320_description/urdf/mycobot_320_m5_2022/force_control_gripper/pro_gripper_base.dae" />
            </geometry>
            <origin rpy="1.5708 0 1.5708" xyz="-0.107 0.012 0.0" />
        </visual>
        <collision>
            <geometry>
                <mesh filename="package://mycobot_320_description/urdf/mycobot_320_m5_2022/force_control_gripper/pro_gripper_base.dae" />
            </geometry>
            <origin rpy="1.5708 0 1.5708" xyz="-0.107 0.012 0.0" />
        </collision>
        <inertial>
            <mass value="0.05" />
            <origin rpy="0 0 0" xyz="0 0 0" />
            <inertia ixx="0.03" ixy="0.0" ixz="0.0" iyy="0.03" iyz="0.0" izz="0.03" />
        </inertial>
    </link>
    <!-- Gripper Left 1 -->
    <link name="gripper_left1">
        <visual>
            <geometry>
                <mesh filename="package://mycobot_320_description/urdf/mycobot_320_m5_2022/force_control_gripper/pro_gripper_left1.dae" />
            </geometry>
            <origin rpy="1.5708 0 1.5708" xyz="-0.047 -0.013 0.044" />
        </visual>
        <collision>
            <geometry>
                <mesh filename="package://mycobot_320_description/urdf/mycobot_320_m5_2022/force_control_gripper/pro_gripper_left1.dae" />
            </geometry>
            <origin rpy="1.5708 0 1.5708" xyz="-0.047 -0.013 0.044" />
        </collision>
        <inertial>
            <mass value="0.005" />
            <origin rpy="0 0 0" xyz="0 0 0" />
            <inertia ixx="0.03" ixy="0.0" ixz="0.0" iyy="0.03" iyz="0.0" izz="0.03" />
        </inertial>
    </link>
    <!-- Gripper Left 2 -->
    <link name="gripper_left2">
        <visual>
            <geometry>
                <mesh filename="package://mycobot_320_description/urdf/mycobot_320_m5_2022/force_control_gripper/pro_gripper_left2.dae" />
            </geometry>
            <origin rpy="3.14159 0 1.5708" xyz="-0.0 0.03 0.004" />
        </visual>
        <collision>
            <geometry>
                <mesh filename="package://mycobot_320_description/urdf/mycobot_320_m5_2022/force_control_gripper/pro_gripper_left2.dae" />
            </geometry>
            <origin rpy="3.14159 0 1.5708" xyz="-0.0 0.03 0.004" />
        </collision>
        <inertial>
            <mass value="0.005" />
            <origin rpy="0 0 0" xyz="0 0 0" />
            <inertia ixx="0.03" ixy="0.0" ixz="0.0" iyy="0.03" iyz="0.0" izz="0.03" />
        </inertial>
    </link>
    <!-- Gripper Left 3 -->
    <link name="gripper_left3">
        <visual>
            <geometry>
                <mesh filename="package://mycobot_320_description/urdf/mycobot_320_m5_2022/force_control_gripper/pro_gripper_left3.dae" />
            </geometry>
            <origin rpy="1.5708 3.14159 1.5708" xyz="0 -0.03 0.012" />
        </visual>
        <collision>
            <geometry>
                <mesh filename="package://mycobot_320_description/urdf/mycobot_320_m5_2022/force_control_gripper/pro_gripper_left3.dae" />
            </geometry>
            <origin rpy="1.5708 3.14159 1.5708" xyz="0 -0.03 0.012" />
        </collision>
        <inertial>
            <mass value="0.005" />
            <origin rpy="0 0 0" xyz="0 0 0" />
            <inertia ixx="0.03" ixy="0.0" ixz="0.0" iyy="0.03" iyz="0.0" izz="0.03" />
        </inertial>
    </link>
    <!-- Gripper Right 1 -->
    <link name="gripper_right1">
        <visual>
            <geometry>
                <mesh filename="package://mycobot_320_description/urdf/mycobot_320_m5_2022/force_control_gripper/pro_gripper_right1.dae" />
            </geometry>
            <origin rpy="1.5708 3.14 -1.5708" xyz="0.047 -0.013 -0.046" />
        </visual>
        <collision>
            <geometry>
                <mesh filename="package://mycobot_320_description/urdf/mycobot_320_m5_2022/force_control_gripper/pro_gripper_right1.dae" />
            </geometry>
            <origin rpy="1.5708 3.14 -1.5708" xyz="0.047 -0.013 -0.046" />
        </collision>
        <inertial>
            <mass value="0.005" />
            <origin rpy="0 0 0" xyz="0 0 0" />
            <inertia ixx="0.03" ixy="0.0" ixz="0.0" iyy="0.03" iyz="0.0" izz="0.033" />
        </inertial>
    </link>
    <!-- Gripper Right 2 -->
    <link name="gripper_right2">
        <visual>
            <geometry>
                <mesh filename="package://mycobot_320_description/urdf/mycobot_320_m5_2022/force_control_gripper/pro_gripper_right2.dae" />
            </geometry>
            <origin rpy="0 0 1.5708" xyz="0 0.03 -0.005" />
        </visual>
        <collision>
            <geometry>
                <mesh filename="package://mycobot_320_description/urdf/mycobot_320_m5_2022/force_control_gripper/pro_gripper_right2.dae" />
            </geometry>
            <origin rpy="0 0 1.5708" xyz="0 0.03 -0.005" />
        </collision>
        <inertial>
            <mass value="0.005" />
            <origin rpy="0 0 0" xyz="0 0 0" />
            <inertia ixx="0.03" ixy="0.0" ixz="0.0" iyy="0.03" iyz="0.0" izz="0.03" />
        </inertial>
    </link>
    <!-- Gripper Right 3 -->
    <link name="gripper_right3">
        <visual>
            <geometry>
                <mesh filename="package://mycobot_320_description/urdf/mycobot_320_m5_2022/force_control_gripper/pro_gripper_right3.dae" />
            </geometry>
            <origin rpy="3.14 0 -1.5708" xyz="-0.014 -0.029 0.004" />
        </visual>
        <collision>
            <geometry>
                <mesh filename="package://mycobot_320_description/urdf/mycobot_320_m5_2022/force_control_gripper/pro_gripper_right3.dae" />
            </geometry>
            <origin rpy="3.14 0 -1.5708" xyz="-0.014 -0.029 0.004" />
        </collision>
        <inertial>
            <mass value="0.005" />
            <origin rpy="0 0 0" xyz="0 0 0" />
            <inertia ixx="0.03" ixy="0.0" ixz="0.0" iyy="0.03" iyz="0.0" izz="0.03" />
        </inertial>
    </link>
    <!-- Joints -->
    <joint name="joint2_to_joint1" type="revolute">
        <axis xyz="0 0 1" />
        <limit effort="1000.0" lower="-2.93" upper="2.93" velocity="1" />
        <parent link="base" />
        <child link="link1" />
        <origin rpy="0 0 0" xyz="0 0 0.173" />
        <dynamics damping="0.1" friction="0.1" />
    </joint>
    <joint name="joint3_to_joint2" type="revolute">
        <axis xyz="0 0 1" />
        <limit effort="1000.0" lower="-2.35" upper="2.35" velocity="1" />
        <parent link="link1" />
        <child link="link2" />
        <origin rpy="0 -1.5708 1.5708" xyz="0 -0.086 0" />
        <dynamics damping="0.1" friction="0.1" />
    </joint>
    <joint name="joint4_to_joint3" type="revolute">
        <axis xyz="0 0 1" />
        <limit effort="1000.0" lower="-2.53" upper="2.53" velocity="1" />
        <parent link="link2" />
        <child link="link3" />
        <origin rpy="0 0 0" xyz="0.13635 0 -0.086" />
        <dynamics damping="0.1" friction="0.1" />
    </joint>
    <joint name="joint5_to_joint4" type="revolute">
        <axis xyz="0 0 1" />
        <limit effort="1000.0" lower="-2.58" upper="2.58" velocity="1" />
        <parent link="link3" />
        <child link="link4" />
        <origin rpy="0 0 1.57080" xyz="0.1195 0 0.082" />
        <dynamics damping="0.1" friction="0.1" />
    </joint>
    <joint name="joint6_to_joint5" type="revolute">
        <axis xyz="0 0 1" />
        <limit effort="1000.0" lower="-2.93" upper="2.93" velocity="1" />
        <parent link="link4" />
        <child link="link5" />
        <origin rpy="1.5708 0 0" xyz="0 -0.09415 0.0" />
        <dynamics damping="0.1" friction="0.1" />
    </joint>
    <joint name="joint6output_to_joint6" type="revolute">
        <axis xyz="0 0 1" />
        <limit effort="1000.0" lower="-3.14" upper="3.14" velocity="1" />
        <parent link="link5" />
        <child link="link6" />
        <origin rpy="-1.5708 0 0" xyz="0 0.055 0.0" />
        <dynamics damping="0.1" friction="0.1" />
    </joint>
    <joint name="joint6output_to_gripper_connect" type="fixed">
        <parent link="link6" />
        <child link="gripper_connection" />
        <origin rpy="0 0 0" xyz="0 0.0 0.01" />
        <dynamics damping="0.1" friction="0.1" />
    </joint>
    <joint name="joint6output_to_gripper_base" type="fixed">
        <parent link="gripper_connection" />
        <child link="gripper_base" />
        <origin rpy="1.5708 0 0" xyz="0 -0.02 0.0364" />
    </joint>
    <!-- Gripper Joints -->
    <joint name="gripper_controller" type="revolute">
        <axis xyz="0 0 1" />
        <limit effort="1000.0" lower="0" upper="1" velocity="1" />
        <parent link="gripper_base" />
        <child link="gripper_left3" />
        <origin rpy="0 0 0" xyz="-0.018 0.016 -0.02" />
        <dynamics damping="20" friction="0.1" />
    </joint>
    <joint name="gripper_base_to_gripper_left2" type="revolute">
        <axis xyz="0 0 1" />
        <limit effort="1000.0" lower="-1" upper="1" velocity="1" />
        <parent link="gripper_base" />
        <child link="gripper_left2" />
        <origin rpy="0 0 0" xyz="-0.0445 -0.004 -0.02" />
        <mimic joint="gripper_controller" multiplier="1.0" offset="0" />
    </joint>
    <joint name="gripper_left3_to_gripper_left1" type="revolute">
        <axis xyz="0 0 1" />
        <limit effort="1000.0" lower="-1" upper="1" velocity="1" />
        <parent link="gripper_left3" />
        <child link="gripper_left1" />
        <origin rpy="0 0 0" xyz="0.01 0.06 0.0" />
        <mimic joint="gripper_controller" multiplier="-1.0" offset="0" />
    </joint>
    <joint name="gripper_base_to_gripper_right3" type="revolute">
        <axis xyz="0 0 1" />
        <limit effort="1000.0" lower="-1" upper="1" velocity="1" />
        <parent link="gripper_base" />
        <child link="gripper_right3" />
        <origin rpy="0 0 0" xyz="0.018 0.015 -0.0212" />
        <mimic joint="gripper_controller" multiplier="-1.0" offset="0" />
    </joint>
    <joint name="gripper_base_to_gripper_right2" type="revolute">
        <axis xyz="0 0 1" />
        <limit effort="1000.0" lower="-1" upper="1" velocity="1" />
        <parent link="gripper_base" />
        <child link="gripper_right2" />
        <origin rpy="0 0 0" xyz="0.0442 -0.004 -0.02" />
        <mimic joint="gripper_controller" multiplier="-1.0" offset="0" />
    </joint>
    <joint name="gripper_right3_to_gripper_right1" type="revolute">
        <axis xyz="0 0 1" />
        <limit effort="1000.0" lower="-1" upper="1" velocity="1" />
        <parent link="gripper_right3" />
        <child link="gripper_right1" />
        <origin rpy="0 0 0" xyz="-0.01 0.061 0.001" />
        <mimic joint="gripper_controller" multiplier="1.0" offset="0" />
    </joint>
    <!-- Transmissions -->
    <transmission name="trans_joint2_to_joint1">
        <type>transmission_interface/SimpleTransmission</type>
        <joint name="joint2_to_joint1">
            <hardwareInterface>hardware_interface/PositionJointInterface</hardwareInterface>
        </joint>
        <actuator name="joint2_to_joint1_motor">
            <hardwareInterface>hardware_interface/PositionJointInterface</hardwareInterface>
            <mechanicalReduction>1</mechanicalReduction>
        </actuator>
    </transmission>
    <transmission name="trans_joint3_to_joint2">
        <type>transmission_interface/SimpleTransmission</type>
        <joint name="joint3_to_joint2">
            <hardwareInterface>hardware_interface/PositionJointInterface</hardwareInterface>
        </joint>
        <actuator name="joint3_to_joint2_motor">
            <hardwareInterface>hardware_interface/PositionJointInterface</hardwareInterface>
            <mechanicalReduction>1</mechanicalReduction>
        </actuator>
    </transmission>
    <transmission name="trans_joint4_to_joint3">
        <type>transmission_interface/SimpleTransmission</type>
        <joint name="joint4_to_joint3">
            <hardwareInterface>hardware_interface/PositionJointInterface</hardwareInterface>
        </joint>
        <actuator name="joint4_to_joint3_motor">
            <hardwareInterface>hardware_interface/PositionJointInterface</hardwareInterface>
            <mechanicalReduction>1</mechanicalReduction>
        </actuator>
    </transmission>
    <transmission name="trans_joint5_to_joint4">
        <type>transmission_interface/SimpleTransmission</type>
        <joint name="joint5_to_joint4">
            <hardwareInterface>hardware_interface/PositionJointInterface</hardwareInterface>
        </joint>
        <actuator name="joint5_to_joint4_motor">
            <hardwareInterface>hardware_interface/PositionJointInterface</hardwareInterface>
            <mechanicalReduction>1</mechanicalReduction>
        </actuator>
    </transmission>
    <transmission name="trans_joint6_to_joint5">
        <type>transmission_interface/SimpleTransmission</type>
        <joint name="joint6_to_joint5">
            <hardwareInterface>hardware_interface/PositionJointInterface</hardwareInterface>
        </joint>
        <actuator name="joint6_to_joint5_motor">
            <hardwareInterface>hardware_interface/PositionJointInterface</hardwareInterface>
            <mechanicalReduction>1</mechanicalReduction>
        </actuator>
    </transmission>
    <transmission name="trans_joint6output_to_joint6">
        <type>transmission_interface/SimpleTransmission</type>
        <joint name="joint6output_to_joint6">
            <hardwareInterface>hardware_interface/PositionJointInterface</hardwareInterface>
        </joint>
        <actuator name="joint6output_to_joint6_motor">
            <hardwareInterface>hardware_interface/PositionJointInterface</hardwareInterface>
            <mechanicalReduction>1</mechanicalReduction>
        </actuator>
    </transmission>
    <transmission name="trans_gripper_controller">
        <type>transmission_interface/SimpleTransmission</type>
        <joint name="gripper_controller">
            <hardwareInterface>hardware_interface/PositionJointInterface</hardwareInterface>
        </joint>
        <actuator name="gripper_controller_motor">
            <hardwareInterface>hardware_interface/PositionJointInterface</hardwareInterface>
            <mechanicalReduction>1</mechanicalReduction>
        </actuator>
    </transmission>
    <!-- Gazebo Plugins -->
    <gazebo>
        <plugin filename="libroboticsgroup_upatras_gazebo_mimic_joint_plugin.so" name="mimic_gripper_base_to_gripper_left2">
            <joint>gripper_controller</joint>
            <mimicJoint>gripper_base_to_gripper_left2</mimicJoint>
            <multiplier>1.0</multiplier>
            <offset>0.0</offset>
        </plugin>
        <plugin filename="libroboticsgroup_upatras_gazebo_mimic_joint_plugin.so" name="mimic_gripper_left3_to_gripper_left1">
            <joint>gripper_controller</joint>
            <mimicJoint>gripper_left3_to_gripper_left1</mimicJoint>
            <multiplier>-1.0</multiplier>
            <offset>0.0</offset>
        </plugin>
        <plugin filename="libroboticsgroup_upatras_gazebo_mimic_joint_plugin.so" name="mimic_gripper_base_to_gripper_right3">
            <joint>gripper_controller</joint>
            <mimicJoint>gripper_base_to_gripper_right3</mimicJoint>
            <multiplier>-1.0</multiplier>
            <offset>0.0</offset>
        </plugin>
        <plugin filename="libroboticsgroup_upatras_gazebo_mimic_joint_plugin.so" name="mimic_gripper_base_to_gripper_right2">
            <joint>gripper_controller</joint>
            <mimicJoint>gripper_base_to_gripper_right2</mimicJoint>
            <multiplier>-1.0</multiplier>
            <offset>0.0</offset>
        </plugin>
        <plugin filename="libroboticsgroup_upatras_gazebo_mimic_joint_plugin.so" name="mimic_gripper_right3_to_gripper_right1">
            <joint>gripper_controller</joint>
            <mimicJoint>gripper_right3_to_gripper_right1</mimicJoint>
            <multiplier>1.0</multiplier>
            <offset>0.0</offset>
        </plugin>
        <plugin filename="libgazebo_ros_control.so" name="gazebo_ros_control">
            <robotNamespace>/</robotNamespace>
        </plugin>
    </gazebo>
    <gazebo reference="base">
        <selfCollide>true</selfCollide>
    </gazebo>
    <gazebo reference="link1">
        <selfCollide>true</selfCollide>
    </gazebo>
    <gazebo reference="link2">
        <selfCollide>true</selfCollide>
    </gazebo>
    <gazebo reference="link3">
        <selfCollide>true</selfCollide>
    </gazebo>
    <gazebo reference="link4">
        <selfCollide>true</selfCollide>
    </gazebo>
    <gazebo reference="link5">
        <selfCollide>true</selfCollide>
    </gazebo>
    <gazebo reference="link6">
        <selfCollide>true</selfCollide>
    </gazebo>
    <gazebo reference="gripper_connection">
        <selfCollide>true</selfCollide>
    </gazebo>
    <gazebo>
        <gripper name="gazebo_gripper">
            <grasp_check>
                <attach_steps>2</attach_steps>
                <detach_steps>2</detach_steps>
                <min_contact_count>3</min_contact_count>
            </grasp_check>
            <gripper_link>gripper_right1</gripper_link>
            <gripper_link>gripper_left1</gripper_link>
            <palm_link>gripper_connection</palm_link>
        </gripper>
    </gazebo>
    <gazebo>
        <plugin filename="libgazebo_grasp_fix.so" name="gazebo_grasp_fix">
            <arm>
                <arm_name>ur5_gripper</arm_name>
                <palm_link>link6</palm_link>
                <gripper_link>gripper_left1</gripper_link>
                <gripper_link>gripper_right1</gripper_link>
                <gripper_link>gripper_right2</gripper_link>
                <gripper_link>gripper_left2</gripper_link>
            </arm>
            <forces_angle_tolerance>150</forces_angle_tolerance>
            <update_rate>130</update_rate>
            <grip_count_threshold>2</grip_count_threshold>
            <max_grip_count>8</max_grip_count>
            <release_tolerance>0.005</release_tolerance>
            <disable_collisions_on_attach>true</disable_collisions_on_attach>
            <contact_topic>__default_topic__</contact_topic>
        </plugin>
    </gazebo>
    <link name="camera_base_link">
        <collision>
            <!-- <origin xyz="0 0 0" rpy="0 0 0"/> -->
            <origin rpy="1.570796327 0 1.570796327" xyz="0 0 0" />
            <geometry>
                <!-- <box size="0.01 0.01 0.01"/> -->
                <mesh filename="package://mycobot_320_description/urdf/d435i.dae" />
            </geometry>
        </collision>
        <visual>
            <!-- <origin xyz="0 0 0" rpy="0 0 0"/> -->
            <origin rpy="1.570796327 0 1.570796327" xyz="0 0 0" />
            <geometry>
                <!-- <box size="0.05 0.1 0.02"/> -->
                <!-- <mesh filename="package://kinect_v2/meshes/kinect2.STL" /> -->
                <!-- <mesh filename="package://robot_sim_demo/models/meshes/xtion_pro_camera.dae" /> -->
                <!-- <mesh filename="package://robot_sim_demo/models/meshes/kinect.dae" /> -->
                <mesh filename="package://mycobot_320_description/urdf/d435i.dae" />
            </geometry>
            <material name="">
                <color rgba="0.0 0.0 0.5 1" />
            </material>
        </visual>
        <inertial>
            <mass value="1e-5" />
            <origin rpy="0 0 0" xyz="0 0 0" />
            <inertia ixx="1e-6" ixy="0" ixz="0" iyy="1e-6" iyz="0" izz="1e-6" />
        </inertial>
    </link>
    <link name="cam_rgb_link" />
    <link name="camera_rgb_optical_frame" />
    <link name="camera_ir_link" />
    <link name="camera_ir_optical_frame" />
    <joint name="camera_rgb_joint" type="fixed">
        <origin rpy="0 0 0" xyz="-0.01 0.0175 0" />
        <parent link="camera_base_link" />
        <child link="cam_rgb_link" />
    </joint>
    <joint name="camera_rgb_optical_frame_joint" type="fixed">
        <origin rpy="-1.570796327 0 -1.570796327" xyz="0 0 0" />
        <parent link="cam_rgb_link" />
        <child link="camera_rgb_optical_frame" />
    </joint>
    <joint name="camera_ir_joint" type="fixed">
        <origin rpy="0 0 0" xyz="0.00 0.015 0.00" />
        <parent link="cam_rgb_link" />
        <child link="camera_ir_link" />
    </joint>
    <joint name="camera_ir_optical_frame_joint" type="fixed">
        <origin rpy="-1.570796327 0 -1.570796327" xyz="0 0 0" />
        <parent link="camera_ir_link" />
        <child link="camera_ir_optical_frame" />
    </joint>
    <gazebo reference="camera_base_link">
        <turnGravityOff>true</turnGravityOff>
    </gazebo>
    <gazebo reference="cam_rgb_link">
        <turnGravityOff>true</turnGravityOff>
    </gazebo>
    <gazebo reference="camera_ir_link">
        <turnGravityOff>true</turnGravityOff>
    </gazebo>
    <gazebo reference="camera_ir_optical_frame">
        <turnGravityOff>true</turnGravityOff>
    </gazebo>
    <gazebo reference="cam_rgb_link">
        <sensor name="cam_rgb_sensor" type="depth">
            <always_on>true</always_on>
            <update_rate>30</update_rate>
            <camera>
                <horizontal_fov>0.9948376737666667</horizontal_fov>
                <image>
                    <format>B8G8R8</format>
                    <width>640</width>
                    <height>480</height>
                </image>
                <clip>
                    <near>0.01</near>
                    <far>5</far>
                </clip>
            </camera>
            <plugin filename="libgazebo_ros_openni_kinect.so" name="cam_rgb_link_controller">
                <alwaysOn>true</alwaysOn>
                <updateRate>30</updateRate>
                <cameraName>camera/rgb</cameraName>
                <imageTopicName>/camera/rgb/image_raw</imageTopicName>
                <cameraInfoTopicName>/camera/rgb/camera_info</cameraInfoTopicName>
                <frameName>camera_rgb_optical_frame</frameName>
                <pointCloudCutoff>0.5</pointCloudCutoff>
                <distortionK1>0</distortionK1>
                <distortionK2>0</distortionK2>
                <distortionK3>0</distortionK3>
                <distortionT1>0</distortionT1>
                <distortionT2>0</distortionT2>
                <CxPrime>0</CxPrime>
                <Cx>320</Cx>
                <Cy>240</Cy>
                <focalLength>0</focalLength>
                <hackBaseline>0</hackBaseline>
            </plugin>
        </sensor>
    </gazebo>
    <gazebo reference="camera_ir_link">
        <sensor name="cam_ir_sensor" type="depth">
            <always_on>true</always_on>
            <update_rate>30</update_rate>
            <camera>
                <horizontal_fov>0.9948376737666667</horizontal_fov>
                <image>
                    <format>L8</format>
                    <width>640</width>
                    <height>480</height>
                </image>
                <clip>
                    <near>0.01</near>
                    <far>5</far>
                </clip>
            </camera>
            <plugin filename="libgazebo_ros_openni_kinect.so" name="camera_ir_link_controller">
                <!-- <baseline>0.2</baseline> -->
                <alwaysOn>true</alwaysOn>
                <updateRate>30</updateRate>
                <cameraName>camera/ir</cameraName>
                <imageTopicName>/camera/ir/image_raw</imageTopicName>
                <cameraInfoTopicName>/camera/ir/camera_info</cameraInfoTopicName>
                <depthImageTopicName>/camera/depth/image_raw</depthImageTopicName>
                <depthImageCameraInfoTopicName>/camera/depth/camera_info</depthImageCameraInfoTopicName>
                <pointCloudTopicName>/camera/depth/points</pointCloudTopicName>
                <frameName>camera_ir_optical_frame</frameName>
                <pointCloudCutoff>0.1</pointCloudCutoff>
                <distortionK1>0</distortionK1>
                <distortionK2>0</distortionK2>
                <distortionK3>0</distortionK3>
                <distortionT1>0</distortionT1>
                <distortionT2>0</distortionT2>
                <CxPrime>0</CxPrime>
                <Cx>320</Cx>
                <Cy>240</Cy>
                <focalLength>0</focalLength>
                <hackBaseline>0</hackBaseline>
            </plugin>
        </sensor>
    </gazebo>
    <joint name="camera_arm" type="fixed">
        <origin rpy="1.5707963 -1.5707963 0 " xyz="0.0 0.05 0.045" />
        <parent link="link6" />
        <child link="camera_base_link" />
    </joint>
    <transmission name="trans_gripper_base_to_gripper_left2">
        <type>transmission_interface/SimpleTransmission</type>
        <joint name="gripper_base_to_gripper_left2">
            <hardwareInterface>hardware_interface/EffortJointInterface</hardwareInterface>
        </joint>
        <actuator name="gripper_base_to_gripper_left2_motor">
            <hardwareInterface>hardware_interface/EffortJointInterface</hardwareInterface>
            <mechanicalReduction>1</mechanicalReduction>
        </actuator>
    </transmission>
    <transmission name="trans_gripper_left3_to_gripper_left1">
        <type>transmission_interface/SimpleTransmission</type>
        <joint name="gripper_left3_to_gripper_left1">
            <hardwareInterface>hardware_interface/EffortJointInterface</hardwareInterface>
        </joint>
        <actuator name="gripper_left3_to_gripper_left1_motor">
            <hardwareInterface>hardware_interface/EffortJointInterface</hardwareInterface>
            <mechanicalReduction>1</mechanicalReduction>
        </actuator>
    </transmission>
    <transmission name="trans_gripper_base_to_gripper_right3">
        <type>transmission_interface/SimpleTransmission</type>
        <joint name="gripper_base_to_gripper_right3">
            <hardwareInterface>hardware_interface/EffortJointInterface</hardwareInterface>
        </joint>
        <actuator name="gripper_base_to_gripper_right3_motor">
            <hardwareInterface>hardware_interface/EffortJointInterface</hardwareInterface>
            <mechanicalReduction>1</mechanicalReduction>
        </actuator>
    </transmission>
    <transmission name="trans_gripper_base_to_gripper_right2">
        <type>transmission_interface/SimpleTransmission</type>
        <joint name="gripper_base_to_gripper_right2">
            <hardwareInterface>hardware_interface/EffortJointInterface</hardwareInterface>
        </joint>
        <actuator name="gripper_base_to_gripper_right2_motor">
            <hardwareInterface>hardware_interface/EffortJointInterface</hardwareInterface>
            <mechanicalReduction>1</mechanicalReduction>
        </actuator>
    </transmission>
    <transmission name="trans_gripper_right3_to_gripper_right1">
        <type>transmission_interface/SimpleTransmission</type>
        <joint name="gripper_right3_to_gripper_right1">
            <hardwareInterface>hardware_interface/EffortJointInterface</hardwareInterface>
        </joint>
        <actuator name="gripper_right3_to_gripper_right1_motor">
            <hardwareInterface>hardware_interface/EffortJointInterface</hardwareInterface>
            <mechanicalReduction>1</mechanicalReduction>
        </actuator>
    </transmission>
</robot>


