<?xml version="1.0" ?>
<robot xmlns:xacro="http://www.ros.org/wiki/xacro" name="firefighter">
    <xacro:property name="width" value=".2" />
    <link name="world" />
    <!-- Base Joint -->
    <joint name="base_joint" type="fixed">
        <parent link="world" />
        <child link="base" />
    </joint>
    <link name="base">
        <visual>
            <geometry>
                <mesh filename="package://mycobot_description/urdf/mycobot_pro_450/PRO450_J1.dae" />
            </geometry>
            <origin xyz="0.0 -0.11 0 " rpy=" 0 0 0" />
        </visual>
        <collision>
            <geometry>
                <cylinder length="0.05" radius="0.053" />
            </geometry>
            <origin xyz="0.0 0.0 0.05" rpy="0 0 1.5708" />
        </collision>
        <selfCollide>true</selfCollide>
        <inertial>
            <mass value="1000.0" />
            <inertia ixx="100" iyy="100" izz="100" ixy="0.0" ixz="0.0" iyz="0.0" />
            <origin xyz="0 0 0" rpy="0 0 0" />
        </inertial>
    </link>
    <link name="link1">
        <visual>
            <geometry>
                <mesh filename="package://mycobot_description/urdf/mycobot_pro_450/PRO450_J2.dae" />
            </geometry>
            <origin xyz="0.0405 0 0.0475 " rpy=" -1.5708 0 -1.5708 " />
        </visual>
        <collision>
            <geometry>
                <cylinder length="0.130" radius="0.033" />
            </geometry>
            <origin xyz="0.0 0 -0.015" rpy="0 0 1.5708" />
        </collision>
        <selfCollide>true</selfCollide>
        <inertial>
            <mass value="20.0" />
            <inertia ixx="1" iyy="1" izz="1" ixy="0.0" ixz="0.0" iyz="0.0" />
            <origin xyz="0 0 0" rpy="0 0 0" />
        </inertial>
    </link>
    <link name="link2">
        <visual>
            <geometry>
                <mesh filename="package://mycobot_description/urdf/mycobot_pro_450/PRO450_J3.dae" />
            </geometry>
            <origin xyz="0.0598 0.005 -0.203 " rpy=" 0 0 1.5708 " />
        </visual>
        <collision>
            <geometry>
                <cylinder length="0.18" radius="0.020" />
            </geometry>
            <origin xyz="0.038 0 0.085" rpy="0 0 0" />
        </collision>
        <selfCollide>true</selfCollide>
        <inertial>
            <mass value="10.0" />
            <inertia ixx="0.5" iyy="0.5" izz="0.5" ixy="0.0" ixz="0.0" iyz="0.0" />
            <origin xyz="0 0 0" rpy="0 0 0" />
        </inertial>
    </link>
    <link name="link3">
        <visual>
            <geometry>
                <mesh filename="package://mycobot_description/urdf/mycobot_pro_450/PRO450_J4.dae" />
            </geometry>
            <origin xyz="0.07 0.005 -0.383 " rpy=" 0 0 1.5708" />
        </visual>
        <collision>
            <geometry>
                <cylinder length="0.2" radius="0.0205" />
            </geometry>
            <origin xyz="-0.04 0.0 0.085" rpy="0 0 0" />
        </collision>
        <selfCollide>true</selfCollide>
        <inertial>
            <mass value="10.0" />
            <inertia ixx="0.5" iyy="0.5" izz="0.5" ixy="0.0" ixz="0.0" iyz="0.0" />
            <origin xyz="0 0 0" rpy="0 0 0" />
        </inertial>
    </link>
    <link name="link4">
        <visual>
            <geometry>
                <mesh filename="package://mycobot_description/urdf/mycobot_pro_450/PRO450_J5.dae" />
            </geometry>
            <origin xyz="-0.015 0 -0.002 " rpy=" 0 -1.5708 0" />
        </visual>
        <collision>
            <geometry>
                <cylinder length="0.06" radius="0.020" />
            </geometry>
            <origin xyz="0.042 -0.0024 0.012" rpy="0 0 1.5708" />
        </collision>
        <selfCollide>true</selfCollide>
        <inertial>
            <mass value="5.0" />
            <inertia ixx="0.2" iyy="0.2" izz="0.2" ixy="0.0" ixz="0.0" iyz="0.0" />
            <origin xyz="0 0 0" rpy="0 0 0" />
        </inertial>
    </link>
    <link name="link5">
        <visual>
            <geometry>
                <mesh filename="package://mycobot_description/urdf/mycobot_pro_450/PRO450_J6.dae" />
            </geometry>
            <origin xyz="0.003 -0.025 -0.608 " rpy=" 0 0 0" />
        </visual>
        <collision>
            <geometry>
                <cylinder length="0.075" radius="0.019" />
            </geometry>
            <origin xyz="0.0 -0.02 0.045" rpy=" -1.5708 0 0" />
        </collision>
        <selfCollide>true</selfCollide>
        <inertial>
            <mass value="5.0" />
            <inertia ixx="0.2" iyy="0.2" izz="0.2" ixy="0.0" ixz="0.0" iyz="0.0" />
            <origin xyz="0 0 0" rpy="0 0 0" />
        </inertial>
    </link>
    <link name="link6">
        <visual>
            <geometry>
                <mesh filename="package://mycobot_description/urdf/mycobot_pro_450/PRO450_J6_end.dae" />
            </geometry>
            <origin xyz="0 0 0.001 " rpy=" 3.14159 0 0" />
        </visual>
        <collision>
            <geometry>
                <cylinder length="0.035" radius="0.024" />
            </geometry>
            <origin xyz="0.007 0.0 0" rpy="0 -1.5708  0" />
        </collision>
        <selfCollide>true</selfCollide>
        <inertial>
            <mass value="5.0" />
            <inertia ixx="0.2" iyy="0.2" izz="0.2" ixy="0.0" ixz="0.0" iyz="0.0" />
            <origin xyz="0 0 0" rpy="0 0 0" />
        </inertial>
    </link>
    <link name="gripper_connection">
        <visual>
            <geometry>
                <mesh filename="package://mycobot_description/urdf/mycobot_320_m5_2022/force_control_gripper/mygripper_f100_connection.dae" />
            </geometry>
            <origin xyz="-0.03 0.014 0" rpy="0 0 -1.5708" />
        </visual>
        <collision>
            <geometry>
                <box size="0.05 0.05 0.03" />
            </geometry>
            <origin xyz="0 0 0" rpy="0 0 0" />
        </collision>
        <selfCollide>true</selfCollide>
        <inertial>
            <mass value="0.1" />
            <inertia ixx="0.1" iyy="0.1" izz="0.1" ixy="0.0" ixz="0.0" iyz="0.0" />
        </inertial>
    </link>
    <link name="gripper_base">
        <visual>
            <geometry>
                <mesh filename="package://mycobot_description/urdf/mycobot_320_m5_2022/force_control_gripper/pro_gripper_base.dae" />
            </geometry>
            <origin xyz="-0.107 0.012 0.0" rpy="1.5708 0 1.5708" />
        </visual>
        <collision>
            <geometry>
                <box size="0.10 0.05 0.035" />
            </geometry>
            <origin xyz="0 0.02 -0.015" rpy="0 0 0" />
        </collision>
        <inertial>
            <mass value="0.005" />
            <origin xyz="0 0 0" rpy="0 0 0" />
            <inertia ixx="0.03" iyy="0.03" izz="0.03" ixy="0.0" ixz="0.0" iyz="0.0" />
        </inertial>
    </link>
    
    <!-- Gripper Left 1 -->
    <link name="gripper_left1">
        <visual>
            <geometry>
                <mesh filename="package://mycobot_description/urdf/mycobot_320_m5_2022/force_control_gripper/pro_gripper_left1.dae" />
            </geometry>
            <origin xyz="-0.047 -0.013 0.044" rpy="1.5708 0 1.5708" />
        </visual>
        <collision>
            <geometry>
                <box size="0.02 0.02 0.055" />
            </geometry>
            <origin xyz="0 0.025 0" rpy="0 0 0" />
        </collision>
        <inertial>
            <mass value="0.005" />
            <origin xyz="0 0 0" rpy="0 0 0" />
            <inertia ixx="0.03" iyy="0.03" izz="0.03" ixy="0.0" ixz="0.0" iyz="0.0" />
        </inertial>
    </link>
    <!-- Gripper Left 2 -->
    <link name="gripper_left2">
        <visual>
            <geometry>
                <mesh filename="package://mycobot_description/urdf/mycobot_320_m5_2022/force_control_gripper/pro_gripper_left2.dae" />
            </geometry>
            <origin xyz="-0.0 0.03 0.004" rpy="3.14159 0 1.5708" />
        </visual>
        <collision>
            <geometry>
                <box size="0.02 0.055 0.02" />
            </geometry>
            <origin xyz="0 0.025 0" rpy="0 0 0" />
        </collision>
        <inertial>
            <mass value="0.005" />
            <origin xyz="0 0 0" rpy="0 0 0" />
            <inertia ixx="0.03" iyy="0.03" izz="0.03" ixy="0.0" ixz="0.0" iyz="0.0" />
        </inertial>
    </link>
    
    <!-- Gripper Left 3 -->
    <link name="gripper_left3">
        <visual>
            <geometry>
                <mesh filename="package://mycobot_description/urdf/mycobot_320_m5_2022/force_control_gripper/pro_gripper_left3.dae" />
            </geometry>
            <origin xyz="0 -0.03 0.012" rpy="1.5708 3.14159 1.5708" />
        </visual>
        <collision>
            <geometry>
                <box size="0.02 0.055 0.02" />
            </geometry>
            <origin xyz="0 0.025 0" rpy="0 0 0" />
        </collision>
        <inertial>
            <mass value="0.005" />
            <origin xyz="0 0 0" rpy="0 0 0" />
            <inertia ixx="0.03" iyy="0.03" izz="0.03" ixy="0.0" ixz="0.0" iyz="0.0" />
        </inertial>
    </link>
    
    <!-- Gripper Right 1 -->
    <link name="gripper_right1">
        <visual>
            <geometry>
                <mesh filename="package://mycobot_description/urdf/mycobot_320_m5_2022/force_control_gripper/pro_gripper_right1.dae" />
            </geometry>
            <origin xyz="0.047 -0.013 -0.046" rpy="1.5708 3.14 -1.5708" />
        </visual>
        <collision>
            <geometry>
                <box size="0.02 0.02 0.055" />
            </geometry>
            <origin xyz="0 0.025 0" rpy="0 0 0" />
        </collision>
        <inertial>
            <mass value="0.005" />
            <origin xyz="0 0 0" rpy="0 0 0" />
            <inertia ixx="0.03" iyy="0.03" izz="0.033" ixy="0.0" ixz="0.0" iyz="0.0" />
        </inertial>
    </link>
    
    <!-- Gripper Right 2 -->
    <link name="gripper_right2">
        <visual>
            <geometry>
                <mesh filename="package://mycobot_description/urdf/mycobot_320_m5_2022/force_control_gripper/pro_gripper_right2.dae" />
            </geometry>
            <origin xyz="0 0.03 -0.005" rpy="0 0 1.5708" />
        </visual>
        <collision>
            <geometry>
                <box size="0.02 0.055 0.02" />
            </geometry>
            <origin xyz="0 0.025 0" rpy="0 0 0" />
        </collision>
        <inertial>
            <mass value="0.005" />
            <origin xyz="0 0 0" rpy="0 0 0" />
            <inertia ixx="0.03" iyy="0.03" izz="0.03" ixy="0.0" ixz="0.0" iyz="0.0" />
        </inertial>
    </link>
    
    <!-- Gripper Right 3 -->
    <link name="gripper_right3">
        <visual>
            <geometry>
                <mesh filename="package://mycobot_description/urdf/mycobot_320_m5_2022/force_control_gripper/pro_gripper_right3.dae" />
            </geometry>
            <origin xyz="-0.014 -0.029 0.004" rpy="3.14 0 -1.5708" />
        </visual>
        <collision>
            <geometry>
                <box size="0.02 0.055 0.02" />
            </geometry>
            <origin xyz="0 0.025 0" rpy="0 0 0" />
        </collision>
        <inertial>
            <mass value="0.005" />
            <origin xyz="0 0 0" rpy="0 0 0" />
            <inertia ixx="0.03" iyy="0.03" izz="0.03" ixy="0.0" ixz="0.0" iyz="0.0" />
        </inertial>
    </link>
    <joint name="joint1" type="revolute">
        <axis xyz="0 0 1" />
        <limit effort="1000.0" lower="-2.8797" upper="2.8797" velocity="1" />
        <parent link="base" />
        <child link="link1" />
        <origin xyz="-0.0045 0 0.155" rpy="0 0 0" />
        <dynamics damping="0.1" friction="0.1" />
    </joint>
    <joint name="joint2" type="revolute">
        <axis xyz="1 0 0" />
        <limit effort="1000.0" lower="-2.0943" upper="2.0943" velocity="1" />
        <parent link="link1" />
        <child link="link2" />
        <origin xyz="0.05 0 0.048" rpy="0 0 0" />
        <dynamics damping="0.1" friction="0.1" />
    </joint>
    <joint name="joint3" type="revolute">
        <axis xyz=" 1 0 0" />
        <limit effort="1000.0" lower="-2.7576" upper="2.7576" velocity="1" />
        <parent link="link2" />
        <child link="link3" />
        <origin xyz="-0.01 0 0.18  " rpy="0 0 0" />
        <dynamics damping="0.1" friction="0.1" />
    </joint>
    <joint name="joint4" type="revolute">
        <axis xyz=" 1 0 0" />
        <limit effort="1000.0" lower="-2.8797" upper="2.8797" velocity="1" />
        <parent link="link3" />
        <child link="link4" />
        <origin xyz="0.0 0 0.1735" rpy="0 0 0" />
        <dynamics damping="0.1" friction="0.1" />
    </joint>
    <joint name="joint5" type="revolute">
        <axis xyz="0 0 1" />
        <limit effort="1000.0" lower="-2.8797" upper="2.8797" velocity="1" />
        <parent link="link4" />
        <child link="link5" />
        <origin xyz="0.046 0.0003 0.05" rpy="0 0 0" />
        <dynamics damping="0.1" friction="0.1" />
    </joint>
    <joint name="joint6" type="revolute">
        <axis xyz="1 0 0" />
        <limit effort="1000.0" lower="-3.0543" upper="3.0543" velocity="1" />
        <parent link="link5" />
        <child link="link6" />
        <origin xyz="0 0.04 0.0435" rpy="0 0 1.5708" />
        <dynamics damping="0.1" friction="0.1" />
    </joint>
    <joint name="joint6_to_gripper_connect" type="fixed">
        <parent link="link6" />
        <child link="gripper_connection" />
        <origin xyz="0.03 0.0 -0.01" rpy="-1.5708 0 -1.5708" />
        <dynamics damping="0.1" friction="0.1" />
    </joint>
    <joint name="joint6_to_gripper_base" type="fixed">
        <parent link="gripper_connection" />
        <child link="gripper_base" />
        <origin xyz="0 -0.02 0.0364" rpy="1.5708 0 0" />
    </joint>
    <joint name="gripper_controller" type="revolute">
        <axis xyz="0 0 1" />
        <limit effort="1000.0" lower="0" upper="1" velocity="1" />
        <parent link="gripper_base" />
        <child link="gripper_left3" />
        <origin xyz="-0.018 0.016 -0.02" rpy="0 0 0" />
        <dynamics damping="10" friction="0.1" />
    </joint>
    <joint name="gripper_base_to_gripper_left2" type="revolute">
        <axis xyz="0 0 1" />
        <limit effort="1000.0" lower="-1" upper="1" velocity="1" />
        <parent link="gripper_base" />
        <child link="gripper_left2" />
        <origin xyz="-0.0445 -0.004 -0.02" rpy="0 0 0" />
        <mimic joint="gripper_controller" multiplier="1.0" offset="0" />
    </joint>
    <joint name="gripper_left3_to_gripper_left1" type="revolute">
        <axis xyz="0 0 1" />
        <limit effort="1000.0" lower="-1" upper="1" velocity="1" />
        <parent link="gripper_left3" />
        <child link="gripper_left1" />
        <origin xyz="0.01 0.06 0.0" rpy="0 0 0" />
        <mimic joint="gripper_controller" multiplier="-1.0" offset="0" />
    </joint>
    <joint name="gripper_base_to_gripper_right3" type="revolute">
        <axis xyz="0 0 1" />
        <limit effort="1000.0" lower="-1" upper="1" velocity="1" />
        <parent link="gripper_base" />
        <child link="gripper_right3" />
        <origin xyz="0.018 0.015 -0.0212" rpy="0 0 0" />
        <mimic joint="gripper_controller" multiplier="-1.0" offset="0" />
    </joint>
    <joint name="gripper_base_to_gripper_right2" type="revolute">
        <axis xyz="0 0 1" />
        <limit effort="1000.0" lower="-1" upper="1" velocity="1" />
        <parent link="gripper_base" />
        <child link="gripper_right2" />
        <origin xyz="0.0442 -0.004 -0.02" rpy="0 0 0" />
        <mimic joint="gripper_controller" multiplier="-1.0" offset="0" />
    </joint>
    <joint name="gripper_right3_to_gripper_right1" type="revolute">
        <axis xyz="0 0 1" />
        <limit effort="1000.0" lower="-1" upper="1" velocity="1" />
        <parent link="gripper_right3" />
        <child link="gripper_right1" />
        <origin xyz="-0.01 0.061 0.001" rpy="0 0 0" />
        <mimic joint="gripper_controller" multiplier="1.0" offset="0" />
    </joint>
    <gazebo>
        <plugin filename="libroboticsgroup_upatras_gazebo_mimic_joint_plugin.so" name="mimic_gripper_base_to_gripper_left2">
            <joint>gripper_controller</joint>
            <mimicJoint>gripper_base_to_gripper_left2</mimicJoint>
            <multiplier>1.0</multiplier>
            <offset>0.0</offset>
        </plugin>
        <plugin filename="libroboticsgroup_upatras_gazebo_mimic_joint_plugin.so" name="mimic_gripper_left3_to_gripper_left1">
            <joint>gripper_controller</joint>
            <mimicJoint>gripper_left3_to_gripper_left1</mimicJoint>
            <multiplier>-1.0</multiplier>
            <offset>0.0</offset>
        </plugin>
        <plugin filename="libroboticsgroup_upatras_gazebo_mimic_joint_plugin.so" name="mimic_gripper_base_to_gripper_right3">
            <joint>gripper_controller</joint>
            <mimicJoint>gripper_base_to_gripper_right3</mimicJoint>
            <multiplier>-1.0</multiplier>
            <offset>0.0</offset>
        </plugin>
        <plugin filename="libroboticsgroup_upatras_gazebo_mimic_joint_plugin.so" name="mimic_gripper_base_to_gripper_right2">
            <joint>gripper_controller</joint>
            <mimicJoint>gripper_base_to_gripper_right2</mimicJoint>
            <multiplier>-1.0</multiplier>
            <offset>0.0</offset>
        </plugin>
        <plugin filename="libroboticsgroup_upatras_gazebo_mimic_joint_plugin.so" name="mimic_gripper_right3_to_gripper_right1">
            <joint>gripper_controller</joint>
            <mimicJoint>gripper_right3_to_gripper_right1</mimicJoint>
            <multiplier>1.0</multiplier>
            <offset>0.0</offset>
        </plugin>
        <plugin name="gazebo_ros_control" filename="libgazebo_ros_control.so">
            <robotNamespace>/</robotNamespace>
        </plugin>
    </gazebo>
    <transmission name="trans_joint1">
        <type>transmission_interface/SimpleTransmission</type>
        <joint name="joint1">
            <hardwareInterface>hardware_interface/PositionJointInterface</hardwareInterface>
        </joint>
        <actuator name="joint1_motor">
            <hardwareInterface>hardware_interface/PositionJointInterface</hardwareInterface>
            <mechanicalReduction>1</mechanicalReduction>
        </actuator>
    </transmission>
    <transmission name="trans_joint2">
        <type>transmission_interface/SimpleTransmission</type>
        <joint name="joint2">
            <hardwareInterface>hardware_interface/PositionJointInterface</hardwareInterface>
        </joint>
        <actuator name="joint2_motor">
            <hardwareInterface>hardware_interface/PositionJointInterface</hardwareInterface>
            <mechanicalReduction>1</mechanicalReduction>
        </actuator>
    </transmission>
    <transmission name="trans_joint3">
        <type>transmission_interface/SimpleTransmission</type>
        <joint name="joint3">
            <hardwareInterface>hardware_interface/PositionJointInterface</hardwareInterface>
        </joint>
        <actuator name="joint3_motor">
            <hardwareInterface>hardware_interface/PositionJointInterface</hardwareInterface>
            <mechanicalReduction>1</mechanicalReduction>
        </actuator>
    </transmission>
    <transmission name="trans_joint4">
        <type>transmission_interface/SimpleTransmission</type>
        <joint name="joint4">
            <hardwareInterface>hardware_interface/PositionJointInterface</hardwareInterface>
        </joint>
        <actuator name="joint4_motor">
            <hardwareInterface>hardware_interface/PositionJointInterface</hardwareInterface>
            <mechanicalReduction>1</mechanicalReduction>
        </actuator>
    </transmission>
    <transmission name="trans_joint5">
        <type>transmission_interface/SimpleTransmission</type>
        <joint name="joint5">
            <hardwareInterface>hardware_interface/PositionJointInterface</hardwareInterface>
        </joint>
        <actuator name="joint5_motor">
            <hardwareInterface>hardware_interface/PositionJointInterface</hardwareInterface>
            <mechanicalReduction>1</mechanicalReduction>
        </actuator>
    </transmission>
    <transmission name="trans_joint6">
        <type>transmission_interface/SimpleTransmission</type>
        <joint name="joint6">
            <hardwareInterface>hardware_interface/PositionJointInterface</hardwareInterface>
        </joint>
        <actuator name="joint6_motor">
            <hardwareInterface>hardware_interface/PositionJointInterface</hardwareInterface>
            <mechanicalReduction>1</mechanicalReduction>
        </actuator>
    </transmission>
    <transmission name="trans_gripper_controller">
        <type>transmission_interface/SimpleTransmission</type>
        <joint name="gripper_controller">
            <hardwareInterface>hardware_interface/PositionJointInterface</hardwareInterface>
        </joint>
        <actuator name="gripper_controller_motor">
            <hardwareInterface>hardware_interface/PositionJointInterface</hardwareInterface>
            <mechanicalReduction>1</mechanicalReduction>
        </actuator>
    </transmission>
    <gazebo reference="base">
        <selfCollide>true</selfCollide>
    </gazebo>
    <gazebo reference="link1">
        <selfCollide>true</selfCollide>
    </gazebo>
    <gazebo reference="link2">
        <selfCollide>true</selfCollide>
    </gazebo>
    <gazebo reference="link3">
        <selfCollide>true</selfCollide>
    </gazebo>
    <gazebo reference="link4">
        <selfCollide>true</selfCollide>
    </gazebo>
    <gazebo reference="link5">
        <selfCollide>true</selfCollide>
    </gazebo>
    <gazebo reference="link6">
        <selfCollide>true</selfCollide>
    </gazebo>
    <gazebo reference="gripper_connection">
        <selfCollide>true</selfCollide>
    </gazebo>
</robot>
